from django.contrib.auth import get_user_model
from posts.models import Comment, Follow, Group, Post
from rest_framework import serializers
from rest_framework.relations import SlugRelatedField
from rest_framework.validators import UniqueTogetherValidator

User = get_user_model()


class PostSerializer(serializers.ModelSerializer):
    """Преобразовывает объекты модели Post."""

    author = SlugRelatedField(slug_field='username', read_only=True)

    class Meta:
        fields = '__all__'
        model = Post


class CommentSerializer(serializers.ModelSerializer):
    """Преобразовывает объекты модели Comment."""

    author = serializers.SlugRelatedField(
        read_only=True, slug_field='username'
    )

    class Meta:
        fields = '__all__'
        model = Comment
        read_only_fields = ('author', 'post',)


class GroupSerializer(serializers.ModelSerializer):
    """Преобразовывает объекты модели Group."""

    class Meta:
        model = Group
        fields = ('id', 'title', 'slug', 'description')


class FollowSerializer(serializers.ModelSerializer):
    """Преобразовывает объекты модели Follow."""

    user = serializers.SlugRelatedField(
        read_only=True, slug_field='username',
        default=serializers.CurrentUserDefault()
    )
    following = serializers.SlugRelatedField(
        slug_field='username', queryset=User.objects.all())

    class Meta:
        model = Follow
        fields = '__all__'
        validators = [
            UniqueTogetherValidator(
                queryset=Follow.objects.all(),
                fields=('user', 'following')
            )
        ]

    def validate(self, data):
        if self.context.get('request').user == data['following']:
            raise serializers.ValidationError(
                'Нельзя подписаться на самого себя'
            )
        return data
